Workbook

Sheet Information

Sheet Depreciation Calculator
C2: Coachx.live
C3: Depreciation Calculator
B5: Straight Line Method
B6: Asset Cost | D6: 450000
B7: Additonal Asset Cost | D7: 50000
B8: Asset Price | D8: =(D6+D7) -> 500000
B9: Scrap Value | D9: 50000
B10: Estimated Life Span (Years) | D10: 10
B11: Depreciation / Year as per Straight Line Method | D11: =(D8-D9)/D10 -> 45000
B12: Depreciation Percentage | D12: =IFERROR(D11/D8,"") -> 0.09
B13: Total Depreciation For Its Life Span | D13: =D11*D10 -> 450000
B14: Depreciated Book Value After Its Life Span | D14: =D9 -> 50000
B15: Balance Amount | D15: =IF(D8="", "", D9-D14) -> 0
B17: Diminishing Balance Method
B18: Asset Cost | D18: 450000
B19: Additonal Asset Cost | D19: 50000
B20: Asset Price | D20: =D18+D19 -> 500000
B21: Scrap Value | D21: 50000
B22: Estimated Life Span (Years) | D22: 10
B23: Rate of Depreciation as per Diminishing Balance Method | D23: =IF(D20="","",1-(D21/D20)^(1/D22)) -> 0.20567177
B24: Depreciation Schedule
B25: Year | C25: Year on Year Depreciation Amount | D25: Book Value
B26: 1 | C26: =D26*D23 -> 102835.88 | D26: =D20 -> 500000
B27: 2 | C27: =D27*0.2057 -> 81696.659 | D27: =D26-C26 -> 397164.12
B28: 3 | C28: =D28*0.2057 -> 64891.656 | D28: =D27-C27 -> 315467.46
B29: 4 | C29: =D29*0.2057 -> 51543.443 | D29: =D28-C28 -> 250575.8
B30: 5 | C30: =D30*0.2057 -> 40940.956 | D30: =D29-C29 -> 199032.36
B31: 6 | C31: =D31*0.2057 -> 32519.402 | D31: =D30-C30 -> 158091.4
B32: 7 | C32: =D32*0.2057 -> 25830.161 | D32: =D31-C31 -> 125572
B33: 8 | C33: =D33*0.2057 -> 20516.897 | D33: =D32-C32 -> 99741.841
B34: 9 | C34: =D34*0.2057 -> 16296.571 | D34: =D33-C33 -> 79224.944
B35: 10 | C35: =D35*0.2057 -> 12944.366 | D35: =D34-C34 -> 62928.373
C36: Scrap Value | D36: =D35-C35 -> 49984.007
C37: =IFERROR(IF(D37>$D$21, (D37*$D$23), ""),"") | D37: =IFERROR(D36-C36, "")
C38: =IFERROR(IF(D38>$D$21, (D38*$D$23), ""),"") | D38: =IFERROR(D37-C37, "")
C39: =IFERROR(IF(D39>$D$21, (D39*$D$23), ""),"") | D39: =IFERROR(D38-C38, "")
C40: =IFERROR(IF(D40>$D$21, (D40*$D$23), ""),"") | D40: =IFERROR(D39-C39, "")
C41: =IFERROR(IF(D41>$D$21, (D41*$D$23), ""),"") | D41: =IFERROR(D40-C40, "")
C42: =IFERROR(IF(D42>$D$21, (D42*$D$23), ""),"") | D42: =IFERROR(D41-C41, "")
C43: =IFERROR(IF(D43>$D$21, (D43*$D$23), ""),"") | D43: =IFERROR(D42-C42, "")
...

Sheet Advanced Problems
B4: Questions | C4: Solutions
B5: 1) Calculate the annual depreciation amount using the straight line method for the given asset. | C5: =('Depreciation Calculator'!D8-'Depreciation Calculator'!D9)/'Depreciation Calculator'!D10 -> 45000
B6: 2) Calculate the total depreciation for the asset's entire life span using the straight-line method. | C6: ='Depreciation Calculator'!D11*'Depreciation Calculator'!D10 -> 450000
B7: 3) What is the depreciated book value of the asset after its life span using the straight-line method? | C7: ='Depreciation Calculator'!D9 -> 50000
B8: 4) Calculate the rate of depreciation per year as per the diminishing balance method. | C8: =IF('Depreciation Calculator'!D20="","",1-('Depreciation Calculator'!D21/'Depreciation Calculator'!D20)^(1/'Depreciation Calculator'!D22)) -> 0.20567177
B9: 5) What is the depreciation amount for the asset in the second year according to the diminishing balance method? | C9: ='Depreciation Calculator'!C27 -> 81696.659
B10: 6) What is the book value of the asset in the fourth year using the diminishing balance method? | C10: ='Depreciation Calculator'!D29 -> 250575.8
B11: 7) Calculate the total depreciation for the asset's entire life span using the diminishing balance method. | C11: ='Depreciation Calculator'!D26-'Depreciation Calculator'!D21 -> 450000
B12: 8) What is the book value of the asset after its life span using the diminishing balance method? | C12: ='Depreciation Calculator'!D21 -> 50000
B13: 9) Compare the total depreciation amounts obtained from the straight-line method and the diminishing balance method. Which method results in higher total depreciation? | C13: Both Methods are Almost Same
B14: 10) Prepare an Presentation for above Analysis you made so far along with Visual Graphs representation | C14: In PPT
